<?xml version="1.0" ?>
<!-- =================================================================================== -->
<!-- |    This document was autogenerated by xacro from furuta_pendulum.urdf.xacro     | -->
<!-- |    EDITING THIS FILE BY HAND IS NOT RECOMMENDED                                 | -->
<!-- =================================================================================== -->
<!-- modified from https://github.com/macstepien/furuta_pendulum/blob/master/furuta_pendulum_description/urdf/furuta_pendulum.urdf.xacro -->
<robot name="furuta_pendulum">
  <material name="grey">
    <color rgba="0.5 0.5 0.5 1.0"/>
  </material>
  <link name="world"/>
  <joint name="world_to_base_joint" type="fixed">
    <origin rpy="0.0 0.0 0.0" xyz="0.0 0.0 0.0"/>
    <parent link="world"/>
    <child link="base_link"/>
  </joint>

  <link name="base_link">
    <visual>
      <origin rpy="0.0 0.0 0.0" xyz="0.0 0.0 0.0895"/>
      <geometry>
        <cylinder length="0.179" radius="0.025"/>
      </geometry>
      <material name="grey"/>
    </visual>
    <collision>
      <origin rpy="0.0 0.0 0.0" xyz="0.0 0.0 0.0895"/>
      <geometry>
        <cylinder length="0.179" radius="0.025"/>
      </geometry>
    </collision>
    <inertial>
      <mass value="10.0"/>
      <origin rpy="0.0 0.0 0.0" xyz="0.0 0.0 0.0"/>
      <inertia ixx="0.1" ixy="0.0" ixz="0.0" iyy="0.1" iyz="0.0" izz="0.1"/>
    </inertial>
  </link>

  <joint name="joint0" type="revolute">
    <origin rpy="0.0 0.0 0.0" xyz="0.0 0.0 0.184"/>
    <parent link="base_link"/>
    <child link="arm1"/>
    <axis xyz="0 0 1"/>
    <dynamics damping="1.16511498e-02"/>
    <limit effort="0.43" velocity="22.0"/>
  </joint>

  <link name="arm1">
    <visual>
      <origin rpy="0.0 1.5707963267948966 0.0" xyz="0.0467625 0.0 0.0"/>
      <geometry>
        <cylinder length="0.093525" radius="0.005"/>
      </geometry>
      <material name="grey"/>
    </visual>
    <collision>
      <origin rpy="0.0 1.5707963267948966 0.0" xyz="0.0467625 0.0 0.0"/>
      <geometry>
        <cylinder length="0.093525" radius="0.005"/>
      </geometry>
    </collision>
    <inertial>
      <mass value="0.040466"/>
      <origin rpy="0.0 0.0 0.0" xyz="0.05415 0.0 0.0"/>
      <inertia ixx="1e-06" ixy="0.0" ixz="0.0" iyy="5.96237099e-04" iyz="0.0" izz="5.96237099e-04"/>
    </inertial>
  </link>
  
  <joint name="joint1" type="revolute">
    <!-- -pi rotation so that for 0 pendulum is downward -->
    <origin rpy="-3.141592653589793 0.0 0.0" xyz="0.093525 0.0 0.0"/>
    <parent link="arm1"/>
    <child link="arm2"/>
    <axis xyz="1 0 0"/>
    <dynamics damping="1.7905703040590617e-05"/>
    <limit effort="0.43" velocity="100.0"/>
  </joint>
  <link name="arm2">
    <visual>
      <origin rpy="0.0 0.0 0.0" xyz="0.0 0.0 0.0645"/>
      <geometry>
        <cylinder length="0.129" radius="0.005"/>
      </geometry>
      <material name="grey"/>
    </visual>
    <collision>
      <origin rpy="0.0 0.0 0.0" xyz="0.0 0.0 0.0645"/>
      <geometry>
        <cylinder length="0.129" radius="0.005"/>
      </geometry>
    </collision>
    <inertial>
      <mass value="0.009801"/>
      <origin rpy="0.0 0.0 0.0" xyz="0.0 0.0 0.096608"/>
      <inertia ixx="0.000014790595" ixy="0.0" ixz="0.0" iyy="0.000014790595" iyz="0.0" izz="1e-06"/>
    </inertial>
  </link>
  <joint name="end_effector_joint" type="fixed">
    <origin rpy="0.0 0.0 0.0" xyz="0.0 0.0 0.129"/>
    <parent link="arm2"/>
    <child link="end_effector"/>
  </joint>
  <link name="end_effector">
</link>
</robot>

